<?xml version="1.0" ?>

<robot name="cabinet_0007_robot" xmlns:xacro="http://ros.org/wiki/xacro">

<xacro:macro name="cabinet_0007" params="ns_prefix parent joint_type xyz rpy scale mesh_dir:=assets/interactive/cabinet_0007">

    <!-- cabinet_0007 -->
    <link name="${ns_prefix}">
        <inertial>
            <origin xyz="0 0 0" />
            <mass value="69.13288766428605" />
            <inertia ixx="0.0" ixy="0.0" ixz="0.0" iyy="0.0" iyz="0.0" izz="0.0" />
        </inertial>
        <visual>
            <origin xyz="0 0 0" />
            <geometry>
                <mesh filename="package://scene_builder/${mesh_dir}/none_motion.obj" rpy="0 0 0" scale="${scale} ${scale} ${scale}"/>
            </geometry>
        </visual>
        <collision>
            <origin xyz="0 0 0" />
            <geometry>
                <mesh filename="package://scene_builder/${mesh_dir}/none_motion.obj" rpy="0 0 0" scale="${scale} ${scale} ${scale}"/>
            </geometry>
        </collision>
    </link>

    <joint name="${ns_prefix}_joint_structure_joint" type="${joint_type}">
        <origin xyz="${xyz}" rpy="${rpy}" />
        <parent link="${parent}" />
        <child link="${ns_prefix}" />
    </joint>
    
    <link name="${ns_prefix}_dof_rootd_Aa002_t">
        <inertial>
            <origin xyz="${-0.0289855 * scale} ${-0.195652 * scale} ${-0.40942 * scale}" />
            <mass value="14.210734497940177" />
            <inertia ixx="0.0" ixy="0.0" ixz="0.0" iyy="0.0" iyz="0.0" izz="0.0" />
        </inertial>
        <visual>
            <origin xyz="${-0.0289855 * scale} ${-0.195652 * scale} ${-0.40942 * scale}" />
            <geometry>
                <mesh filename="package://scene_builder/${mesh_dir}/dof_rootd_Aa002_t.obj" rpy="0 0 0" scale="${scale} ${scale} ${scale}"/>
            </geometry>
        </visual>
        <collision>
            <origin xyz="${-0.0289855 * scale} ${-0.195652 * scale} ${-0.40942 * scale}" />
            <geometry>
                <mesh filename="package://scene_builder/${mesh_dir}/dof_rootd_Aa002_t.obj" rpy="0 0 0" scale="${scale} ${scale} ${scale}"/>
            </geometry>
        </collision>
    </link>

    <joint name="${ns_prefix}_dof_rootd_Aa002_t_joint" type="prismatic">
        <origin xyz="${0.0289855 * scale} ${0.195652 * scale} ${0.40942 * scale}" rpy="0 0 0" />
        <parent link="${ns_prefix}" />
        <child link="${ns_prefix}_dof_rootd_Aa002_t" />
        <axis xyz="1.0 0.0 2.22045e-16" />
        <dynamics friction="0.4361130912842518" />
        <limit effort="0.0" velocity="0.5" lower="0.0" upper="0.5157770751959618" />
    </joint>
    
        
    
    <link name="${ns_prefix}_dof_rootd_Aa003_t">
        <inertial>
            <origin xyz="${-0.0289855 * scale} ${3.41916e-17 * scale} ${-0.205918 * scale}" />
            <mass value="4.976905577005404" />
            <inertia ixx="0.0" ixy="0.0" ixz="0.0" iyy="0.0" iyz="0.0" izz="0.0" />
        </inertial>
        <visual>
            <origin xyz="${-0.0289855 * scale} ${3.41916e-17 * scale} ${-0.205918 * scale}" />
            <geometry>
                <mesh filename="package://scene_builder/${mesh_dir}/dof_rootd_Aa003_t.obj" rpy="0 0 0" scale="${scale} ${scale} ${scale}"/>
            </geometry>
        </visual>
        <collision>
            <origin xyz="${-0.0289855 * scale} ${3.41916e-17 * scale} ${-0.205918 * scale}" />
            <geometry>
                <mesh filename="package://scene_builder/${mesh_dir}/dof_rootd_Aa003_t.obj" rpy="0 0 0" scale="${scale} ${scale} ${scale}"/>
            </geometry>
        </collision>
    </link>

    <joint name="${ns_prefix}_dof_rootd_Aa003_t_joint" type="prismatic">
        <origin xyz="${0.0289855 * scale} ${-3.41916e-17 * scale} ${0.205918 * scale}" rpy="0 0 0" />
        <parent link="${ns_prefix}" />
        <child link="${ns_prefix}_dof_rootd_Aa003_t" />
        <axis xyz="1.0 -3.46945e-18 1.11022e-16" />
        <dynamics friction="0.3986385132017317" />
        <limit effort="0.0" velocity="0.5" lower="0.0" upper="0.3787505950500847"/>
    </joint>
    
        
    
    <link name="${ns_prefix}_dof_rootd_Aa004_t">
        <inertial>
            <origin xyz="${-0.0289855 * scale} ${3.41916e-17 * scale} ${0.030797 * scale}" />
            <mass value="13.176503188441188" />
            <inertia ixx="0.0" ixy="0.0" ixz="0.0" iyy="0.0" iyz="0.0" izz="0.0" />
        </inertial>
        <visual>
            <origin xyz="${-0.0289855 * scale} ${3.41916e-17 * scale} ${0.030797 * scale}" />
            <geometry>
                <mesh filename="package://scene_builder/${mesh_dir}/dof_rootd_Aa004_t.obj" rpy="0 0 0" scale="${scale} ${scale} ${scale}"/>
            </geometry>
        </visual>
        <collision>
            <origin xyz="${-0.0289855 * scale} ${3.41916e-17 * scale} ${0.030797 * scale}" />
            <geometry>
                <mesh filename="package://scene_builder/${mesh_dir}/dof_rootd_Aa004_t.obj" rpy="0 0 0" scale="${scale} ${scale} ${scale}"/>
            </geometry>
        </collision>
    </link>

    <joint name="${ns_prefix}_dof_rootd_Aa004_t_joint" type="prismatic">
        <origin xyz="${0.0289855 * scale} ${-3.41916e-17 * scale} ${-0.030797 * scale}" rpy="0 0 0" />
        <parent link="${ns_prefix}" />
        <child link="${ns_prefix}_dof_rootd_Aa004_t" />
        <axis xyz="1.0 -3.46945e-18 1.17961e-16" />
        <dynamics friction="0.13023228421441493" />
        <limit effort="0.0" velocity="0.5" lower="0.0" upper="0.6654154099311045"/>
    </joint>
    
        
    
    <link name="${ns_prefix}_dof_rootd_Aa005_t">
        <inertial>
            <origin xyz="${-0.0289855 * scale} ${6.43608e-18 * scale} ${0.267512 * scale}" />
            <mass value="10.774830347907187" />
            <inertia ixx="0.0" ixy="0.0" ixz="0.0" iyy="0.0" iyz="0.0" izz="0.0" />
        </inertial>
        <visual>
            <origin xyz="${-0.0289855 * scale} ${6.43608e-18 * scale} ${0.267512 * scale}" />
            <geometry>
                <mesh filename="package://scene_builder/${mesh_dir}/dof_rootd_Aa005_t.obj" rpy="0 0 0" scale="${scale} ${scale} ${scale}"/>
            </geometry>
        </visual>
        <collision>
            <origin xyz="${-0.0289855 * scale} ${6.43608e-18 * scale} ${0.267512 * scale}" />
            <geometry>
                <mesh filename="package://scene_builder/${mesh_dir}/dof_rootd_Aa005_t.obj" rpy="0 0 0" scale="${scale} ${scale} ${scale}"/>
            </geometry>
        </collision>
    </link>

    <joint name="${ns_prefix}_dof_rootd_Aa005_t_joint" type="prismatic">
        <origin xyz="${0.0289855 * scale} ${-6.43608e-18 * scale} ${-0.267512 * scale}" rpy="0 0 0" />
        <parent link="${ns_prefix}" />
        <child link="${ns_prefix}_dof_rootd_Aa005_t" />
        <axis xyz="1.0 2.77556e-17 1.11022e-16" />
        <dynamics friction="0.853818395858771" />
        <limit effort="0.0" velocity="0.5" lower="0.0" upper="0.5732757742927763"/>
    </joint>
    
    <link name="${ns_prefix}_dof_rootd_Aa001_t">
        <inertial>
            <origin xyz="${-0.0289855 * scale} ${0.195652 * scale} ${-0.40942 * scale}" />
            <mass value="5.510538026402097" />
            <inertia ixx="0.0" ixy="0.0" ixz="0.0" iyy="0.0" iyz="0.0" izz="0.0" />
        </inertial>
        <visual>
            <origin xyz="${-0.0289855 * scale} ${0.195652 * scale} ${-0.40942 * scale}" />
            <geometry>
                <mesh filename="package://scene_builder/${mesh_dir}/dof_rootd_Aa001_t.obj" rpy="0 0 0" scale="${scale} ${scale} ${scale}"/>
            </geometry>
        </visual>
        <collision>
            <origin xyz="${-0.0289855 * scale} ${0.195652 * scale} ${-0.40942 * scale}" />
            <geometry>
                <mesh filename="package://scene_builder/${mesh_dir}/dof_rootd_Aa001_t.obj" rpy="0 0 0" scale="${scale} ${scale} ${scale}"/>
            </geometry>
        </collision>
    </link>

    <joint name="${ns_prefix}_dof_rootd_Aa001_t_joint" type="prismatic">
        <origin xyz="${0.0289855 * scale} ${-0.195652 * scale} ${0.40942 * scale}" rpy="0 0 0" />
        <parent link="${ns_prefix}" />
        <child link="${ns_prefix}_dof_rootd_Aa001_t" />
        <axis xyz="1.0 0.0 1.66533e-16" />
        <dynamics friction="0.5167102184541688" />
        <limit effort="0.0" velocity="0.5" lower="0.0" upper="0.3507672997975942"/>
    </joint>

</xacro:macro>
    
</robot>
        