<?xml version="1.0" ?>

<robot name="cabinet_0007_robot" >

    <link name="world" />

<!-- cabinet_0007 -->

    <!-- cabinet_0007 -->
    <link name="cabinet_0007">
        <inertial>
            <origin xyz="0 0 0" />
            <mass value="69.13288766428605" />
            <inertia ixx="0.0" ixy="0.0" ixz="0.0" iyy="0.0" iyz="0.0" izz="0.0" />
        </inertial>
        <visual>
            <origin xyz="0 0 0" />
            <geometry>
                <mesh filename="package://scene_builder/assets/interactive/cabinet_0007/none_motion.obj" rpy="0 0 0" />
            </geometry>
        </visual>
        <collision>
            <origin xyz="0 0 0" />
            <geometry>
                <mesh filename="package://scene_builder/assets/interactive/cabinet_0007/none_motion.obj" rpy="0 0 0" />
            </geometry>
        </collision>
    </link>


    <joint name="joint_structure_joint" type="fixed">
        <origin xyz="0.000 0.000 0.000" rpy="0 0 0" />
        <parent link="world" />
        <child link="cabinet_0007" />
    </joint>

    
    <link name="dof_rootd_Aa002_t">
        <inertial>
            <origin xyz="-0.0289855 -0.195652 -0.40942" />
            <mass value="14.210734497940177" />
            <inertia ixx="0.0" ixy="0.0" ixz="0.0" iyy="0.0" iyz="0.0" izz="0.0" />
        </inertial>
        <visual>
            <origin xyz="-0.0289855 -0.195652 -0.40942" />
            <geometry>
                <mesh filename="package://scene_builder/assets/interactive/cabinet_0007/dof_rootd_Aa002_t.obj" rpy="0 0 0" />
            </geometry>
        </visual>
        <collision>
            <origin xyz="-0.0289855 -0.195652 -0.40942" />
            <geometry>
                <mesh filename="package://scene_builder/assets/interactive/cabinet_0007/dof_rootd_Aa002_t.obj" rpy="0 0 0" />
            </geometry>
        </collision>
    </link>

    <joint name="dof_rootd_Aa002_t_joint" type="prismatic">
        <origin xyz="0.0289855 0.195652 0.40942" rpy="0 0 0" />
        <parent link="cabinet_0007" />
        <child link="dof_rootd_Aa002_t" />
        <axis xyz="1.0 0.0 2.22045e-16" />
        <dynamics friction="0.4361130912842518" />
        <limit effort="0.0" velocity="0.5" lower="0.0" upper="0.5157770751959618" />
    </joint>
    
        
    
    <link name="dof_rootd_Aa003_t">
        <inertial>
            <origin xyz="-0.0289855 3.41916e-17 -0.205918" />
            <mass value="4.976905577005404" />
            <inertia ixx="0.0" ixy="0.0" ixz="0.0" iyy="0.0" iyz="0.0" izz="0.0" />
        </inertial>
        <visual>
            <origin xyz="-0.0289855 3.41916e-17 -0.205918" />
            <geometry>
                <mesh filename="package://scene_builder/assets/interactive/cabinet_0007/dof_rootd_Aa003_t.obj" rpy="0 0 0" />
            </geometry>
        </visual>
        <collision>
            <origin xyz="-0.0289855 3.41916e-17 -0.205918" />
            <geometry>
                <mesh filename="package://scene_builder/assets/interactive/cabinet_0007/dof_rootd_Aa003_t.obj" rpy="0 0 0" />
            </geometry>
        </collision>
    </link>

    <joint name="dof_rootd_Aa003_t_joint" type="prismatic">
        <origin xyz="0.0289855 -3.41916e-17 0.205918" rpy="0 0 0" />
        <parent link="cabinet_0007" />
        <child link="dof_rootd_Aa003_t" />
        <axis xyz="1.0 -3.46945e-18 1.11022e-16" />
        <dynamics friction="0.3986385132017317" />
        <limit effort="0.0" velocity="0.5" lower="0.0" upper="0.3787505950500847"/>
    </joint>
    
        
    
    <link name="dof_rootd_Aa004_t">
        <inertial>
            <origin xyz="-0.0289855 3.41916e-17 0.030797" />
            <mass value="13.176503188441188" />
            <inertia ixx="0.0" ixy="0.0" ixz="0.0" iyy="0.0" iyz="0.0" izz="0.0" />
        </inertial>
        <visual>
            <origin xyz="-0.0289855 3.41916e-17 0.030797" />
            <geometry>
                <mesh filename="package://scene_builder/assets/interactive/cabinet_0007/dof_rootd_Aa004_t.obj" rpy="0 0 0" />
            </geometry>
        </visual>
        <collision>
            <origin xyz="-0.0289855 3.41916e-17 0.030797" />
            <geometry>
                <mesh filename="package://scene_builder/assets/interactive/cabinet_0007/dof_rootd_Aa004_t.obj" rpy="0 0 0" />
            </geometry>
        </collision>
    </link>

    <joint name="dof_rootd_Aa004_t_joint" type="prismatic">
        <origin xyz="0.0289855 -3.41916e-17 -0.030797" rpy="0 0 0" />
        <parent link="cabinet_0007" />
        <child link="dof_rootd_Aa004_t" />
        <axis xyz="1.0 -3.46945e-18 1.17961e-16" />
        <dynamics friction="0.13023228421441493" />
        <limit effort="0.0" velocity="0.5" lower="0.0" upper="0.6654154099311045"/>
    </joint>
    
        
    
    <link name="dof_rootd_Aa005_t">
        <inertial>
            <origin xyz="-0.0289855 6.43608e-18 0.267512" />
            <mass value="10.774830347907187" />
            <inertia ixx="0.0" ixy="0.0" ixz="0.0" iyy="0.0" iyz="0.0" izz="0.0" />
        </inertial>
        <visual>
            <origin xyz="-0.0289855 6.43608e-18 0.267512" />
            <geometry>
                <mesh filename="package://scene_builder/assets/interactive/cabinet_0007/dof_rootd_Aa005_t.obj" rpy="0 0 0" />
            </geometry>
        </visual>
        <collision>
            <origin xyz="-0.0289855 6.43608e-18 0.267512" />
            <geometry>
                <mesh filename="package://scene_builder/assets/interactive/cabinet_0007/dof_rootd_Aa005_t.obj" rpy="0 0 0" />
            </geometry>
        </collision>
    </link>

    <joint name="dof_rootd_Aa005_t_joint" type="prismatic">
        <origin xyz="0.0289855 -6.43608e-18 -0.267512" rpy="0 0 0" />
        <parent link="cabinet_0007" />
        <child link="dof_rootd_Aa005_t" />
        <axis xyz="1.0 2.77556e-17 1.11022e-16" />
        <dynamics friction="0.853818395858771" />
        <limit effort="0.0" velocity="0.5" lower="0.0" upper="0.5732757742927763"/>
    </joint>
    
    <link name="dof_rootd_Aa001_t">
        <inertial>
            <origin xyz="-0.0289855 0.195652 -0.40942" />
            <mass value="5.510538026402097" />
            <inertia ixx="0.0" ixy="0.0" ixz="0.0" iyy="0.0" iyz="0.0" izz="0.0" />
        </inertial>
        <visual>
            <origin xyz="-0.0289855 0.195652 -0.40942" />
            <geometry>
                <mesh filename="package://scene_builder/assets/interactive/cabinet_0007/dof_rootd_Aa001_t.obj" rpy="0 0 0" />
            </geometry>
        </visual>
        <collision>
            <origin xyz="-0.0289855 0.195652 -0.40942" />
            <geometry>
                <mesh filename="package://scene_builder/assets/interactive/cabinet_0007/dof_rootd_Aa001_t.obj" rpy="0 0 0" />
            </geometry>
        </collision>
    </link>

    <joint name="dof_rootd_Aa001_t_joint" type="prismatic">
        <origin xyz="0.0289855 -0.195652 0.40942" rpy="0 0 0" />
        <parent link="cabinet_0007" />
        <child link="dof_rootd_Aa001_t" />
        <axis xyz="1.0 0.0 1.66533e-16" />
        <dynamics friction="0.5167102184541688" />
        <limit effort="0.0" velocity="0.5" lower="0.0" upper="0.3507672997975942"/>
    </joint>
    
</robot>
        