<?xml version="1.0"?>

<robot name="cabinet_0001_robot" >

    <link name="world" />


<!-- cabinet_0001 -->

    <!-- cabinet_0001 -->
    <link name="cabinet_0001">
        <inertial>
            <origin xyz="0 0 0" />
            <mass value="33.18129099222546" />
            <inertia ixx="0.0" ixy="0.0" ixz="0.0" iyy="0.0" iyz="0.0" izz="0.0" />
        </inertial>
        <visual>
            <origin xyz="0 0 0" />
            <geometry>
                <mesh filename="package://scene_builder/assets/interactive/cabinet_0001/none_motion.obj" rpy="0 0 0" />
            </geometry>
        </visual>
        <collision>
            <origin xyz="0 0 0" />
            <geometry>
                <mesh filename="package://scene_builder/assets/interactive/cabinet_0001/none_motion.obj" rpy="0 0 0" />
            </geometry>
        </collision>
    </link>


    <joint name="joint_structure" type="fixed">
        <origin xyz="0.000 0.000 0.000" rpy="0 0 0" />
        <parent link="world" />
        <child link="cabinet_0001" />
    </joint>


    
    <link name="dof_rootd_Bb001_r">
        <inertial>
            <origin xyz="-0.129865 -0.138132 -0.0233064" />
            <mass value="4.60682560178928" />
            <inertia ixx="0.0" ixy="0.0" ixz="0.0" iyy="0.0" iyz="0.0" izz="0.0" />
        </inertial>
        <visual>
            <origin xyz="-0.129865 -0.138132 -0.0233064" />
            <geometry>
                <mesh filename="package://scene_builder/assets/interactive/cabinet_0001/dof_rootd_Bb001_r.obj" rpy="0 0 0" />
            </geometry>
        </visual>
        <collision>
            <origin xyz="-0.129865 -0.138132 -0.0233064" />
            <geometry>
                <mesh filename="package://scene_builder/assets/interactive/cabinet_0001/dof_rootd_Bb001_r.obj" rpy="0 0 0" />
            </geometry>
        </collision>
    </link>

    <joint name="dof_rootd_Bb001_r" type="revolute">
        <origin xyz="0.129865 0.138132 0.0233064" rpy="0 0 0" />
        <parent link="cabinet_0001" />
        <child link="dof_rootd_Bb001_r" />
        <axis xyz="0.0 2.22045e-16 1.0" />
        <dynamics friction="0.4794564749794503" />
        <limit effort="0.0" velocity="0.5" lower="0.0" upper="0.5947299007132142"/>
    </joint>
    
        

</robot>
        