<?xml version='1.0' encoding='UTF-8'?>
<robot xmlns:xacro="http://ros.org/wiki/xacro" name="scene">

  <!-- ridgeback robot begin -->
  <xacro:include filename="$(find ridgeback_dual_arm_description)/urdf/ridgeback_dual_arm.urdf.xacro" />
  
  <!-- Arguments -->
  <xacro:arg name="base_loc_x" default="0.0"/>
  <xacro:arg name="base_loc_y" default="0.0"/>
  <xacro:arg name="base_loc_orient" default="0.0"/>
  <xacro:arg name="robot_prefix" default=""/>

  <!-- Setup Environment -->
  <!-- 
    link order: world link -> virtual_base_x -> virtual_base_y -> virtual_base_theta -> base_link 
  -->

  <link name="$(arg robot_prefix)virtual_base_theta"/>
  <joint name="$(arg robot_prefix)base_link_base_theta" type="revolute">
  <!-- <joint name="$(arg robot_prefix)base_link_base_theta" type="continuous"> -->
    <parent link="$(arg robot_prefix)virtual_base_theta" />
    <origin xyz="0.0 0.0 0.0" rpy="0 0 0" />
    <child link="base_link" />
    <axis xyz="0 0 1"/>
    <limit effort="20" velocity="5.0" lower="-3.14" upper="3.14"/>
    <!-- <limit effort="20" velocity="5.0"/> -->
  </joint>

  <link name="$(arg robot_prefix)virtual_base_y"/>
  <joint name="$(arg robot_prefix)base_theta_base_y" type="prismatic">
    <parent link="$(arg robot_prefix)virtual_base_y" />
    <origin xyz="0.0 0.0 0.0" rpy="0 0 0" />
    <child link="$(arg robot_prefix)virtual_base_theta" />
    <axis xyz="0 1 0"/>
    <limit effort="20" velocity="5.0" lower="-10" upper="10"/>
  </joint>

  <link name="$(arg robot_prefix)virtual_base_x"/>
  <joint name="$(arg robot_prefix)base_y_base_x" type="prismatic">
    <parent link="$(arg robot_prefix)virtual_base_x" />
    <origin xyz="0.0 0.0 0.0" rpy="0 0 0" />
    <child link="$(arg robot_prefix)virtual_base_y" />
    <axis xyz="1 0 0"/>
    <limit effort="20" velocity="5.0" lower="-10" upper="10"/>
  </joint>


  <link name="world"/>
  <joint name="world_to_base_footprint" type="fixed">
    <parent link="world"/>
    <child link="$(arg robot_prefix)virtual_base_x"/>
    <origin xyz="$(arg base_loc_x) $(arg base_loc_y) 0.01965" rpy="0 0 $(arg base_loc_orient)" />
  </joint>


  <!-- ridgeback robot end -->
</robot>
