<?xml version="1.0"?>
<robot name="husky_ur5e_2f_85" xmlns:xacro="http://www.ros.org/wiki/xacro">

  <xacro:include filename="$(find husky_ur_description)/urdf/husky_ur5_e_description.urdf.xacro" />

  <joint name="2f_85_joint" type="fixed">
    <origin rpy="0.0 ${M_PI/2} 0" xyz="0.0 0.0 0.0" />
    <parent link="ur_arm_ee_link" />
    <child link="robotiq_arg2f_base_link" />
  </joint>
  <xacro:macro name="deploy" params="prefix attach_to_world loc_x loc_y orientation has_gripper">

    <!-- Virtual Link Starts -->
    <link name="${prefix}virtual_base_x" />

    <link name="${prefix}virtual_base_y" />

    <link name="${prefix}virtual_base_theta" />
    <!-- Virtual Link Ends -->

    <joint name="${prefix}base_link_base_theta" type="revolute">
      <parent link="${prefix}virtual_base_theta" />
      <origin xyz="0.0 0.0 0.0" rpy="0 0 0" />
      <child link="base_link" />
      <axis xyz="0 0 1" />
      <limit effort="20" velocity="5.0" lower="-6.28" upper="6.28" />
    </joint>

    <joint name="${prefix}base_theta_base_y" type="prismatic">
      <parent link="${prefix}virtual_base_y" />
      <origin xyz="0.0 0.0 0.0" rpy="0 0 0" />
      <child link="${prefix}virtual_base_theta" />
      <axis xyz="0 1 0" />
      <limit effort="20" velocity="5.0" lower="-10" upper="10" />
    </joint>

    <joint name="${prefix}base_y_base_x" type="prismatic">
      <parent link="${prefix}virtual_base_x" />
      <origin xyz="0.0 0.0 0.0" rpy="0 0 0" />
      <child link="${prefix}virtual_base_y" />
      <axis xyz="1 0 0" />
      <limit effort="20" velocity="5.0" lower="-10" upper="10" />
    </joint>

    <xacro:if value="${attach_to_world}">
      <joint name="${prefix}world" type="fixed">
        <child link="${prefix}virtual_base_x" />
        <parent link="world" />
        <origin xyz="${loc_x} ${loc_y} 0.145" rpy="0 0 ${orientation}" />
      </joint>
    </xacro:if>

    <xacro:if value="${has_gripper}">
      <xacro:include filename="$(find robotiq_2f_85_gripper_visualization)/urdf/robotiq_arg2f_85_model_macro.xacro" />
      <xacro:robotiq_arg2f_85 prefix="" />
    </xacro:if>

  </xacro:macro>
</robot>